---   SHUT DOWN.   ---
---   SHUT DOWN.   ---
--- STARTING UP... ---
---   CONNECTED.   ---
Connected!
[VB] User Hyperboid sent message "w"
[VB] User Hyperboid sent message "/tt rl"
[VB] User Tommy Trusty sent message "Restarting!"
_ClientEventTask exception was never retrieved
future: <ClientEventTask state=finished event=on_message coro=<function on_message at 0x7fc373662b80> exception=SystemExit(None)>
Traceback (most recent call last):
  File "/home/hyper/.local/lib/python3.9/site-packages/discord/client.py", line 698, in run
    loop.run_forever()
  File "/usr/lib/python3.9/asyncio/base_events.py", line 596, in run_forever
    self._run_once()
  File "/usr/lib/python3.9/asyncio/base_events.py", line 1890, in _run_once
    handle._run()
  File "/usr/lib/python3.9/asyncio/events.py", line 80, in _run
    self._context.run(self._callback, *self._args)
  File "/home/hyper/.local/lib/python3.9/site-packages/discord/client.py", line 333, in _run_event
    await coro(*args, **kwargs)
  File "/home/hyper/Documents/Coding/Python/DiscordBot/bot.py", line 112, in on_message
    await bot.process_commands(message)
  File "/home/hyper/.local/lib/python3.9/site-packages/discord/ext/commands/bot.py", line 940, in process_commands
    await self.invoke(ctx)
  File "/home/hyper/.local/lib/python3.9/site-packages/discord/ext/commands/bot.py", line 903, in invoke
    await ctx.command.invoke(ctx)
  File "/home/hyper/.local/lib/python3.9/site-packages/discord/ext/commands/core.py", line 859, in invoke
    await injected(*ctx.args, **ctx.kwargs)
  File "/home/hyper/.local/lib/python3.9/site-packages/discord/ext/commands/core.py", line 85, in wrapped
    ret = await coro(*args, **kwargs)
  File "/home/hyper/Documents/Coding/Python/DiscordBot/bot.py", line 69, in command_reboot
    quit()
  File "/usr/lib/python3.9/_sitebuiltins.py", line 26, in __call__
    raise SystemExit(code)
SystemExit: None
---   SHUT DOWN.   ---
--- STARTING UP... ---
---   CONNECTED.   ---
Connected!
[VB] User Hyperboid sent message "/tt rl"
[VB] User Tommy Trusty sent message "Restarting!"
_ClientEventTask exception was never retrieved
future: <ClientEventTask state=finished event=on_message coro=<function on_message at 0x7f1f02d23b80> exception=SystemExit(None)>
Traceback (most recent call last):
  File "/home/hyper/.local/lib/python3.9/site-packages/discord/client.py", line 698, in run
    loop.run_forever()
  File "/usr/lib/python3.9/asyncio/base_events.py", line 596, in run_forever
    self._run_once()
  File "/usr/lib/python3.9/asyncio/base_events.py", line 1890, in _run_once
    handle._run()
  File "/usr/lib/python3.9/asyncio/events.py", line 80, in _run
    self._context.run(self._callback, *self._args)
  File "/home/hyper/.local/lib/python3.9/site-packages/discord/client.py", line 333, in _run_event
    await coro(*args, **kwargs)
  File "/home/hyper/Documents/Coding/Python/DiscordBot/bot.py", line 112, in on_message
    bad_words = '|'.join(s for l in f for s in l.split(', '))
  File "/home/hyper/.local/lib/python3.9/site-packages/discord/ext/commands/bot.py", line 940, in process_commands
    await self.invoke(ctx)
  File "/home/hyper/.local/lib/python3.9/site-packages/discord/ext/commands/bot.py", line 903, in invoke
    await ctx.command.invoke(ctx)
  File "/home/hyper/.local/lib/python3.9/site-packages/discord/ext/commands/core.py", line 859, in invoke
    await injected(*ctx.args, **ctx.kwargs)
  File "/home/hyper/.local/lib/python3.9/site-packages/discord/ext/commands/core.py", line 85, in wrapped
    ret = await coro(*args, **kwargs)
  File "/home/hyper/Documents/Coding/Python/DiscordBot/bot.py", line 69, in command_reboot
    async def command_id(ctx):
  File "/usr/lib/python3.9/_sitebuiltins.py", line 26, in __call__
    raise SystemExit(code)
SystemExit: None
---   SHUT DOWN.   ---
Ignoring exception in command None:
discord.ext.commands.errors.CommandNotFound: Command "clear" is not found
--- STARTING UP... ---
---   CONNECTED.   ---
Connected!
[VB] User Hyperboid sent message ""
[VB] User Hyperboid sent message "/tmy test"
[VB] User Tommy Trusty sent message ""
[VB] User Hyperboid sent message "/tt clear"
[VB] User Hyperboid sent message "/tt rl"
[VB] User Tommy Trusty sent message "Restarting!"
_ClientEventTask exception was never retrieved
future: <ClientEventTask state=finished event=on_message coro=<function on_message at 0x7f9be4c40ca0> exception=SystemExit(None)>
Traceback (most recent call last):
  File "/home/hyper/.local/lib/python3.9/site-packages/discord/client.py", line 698, in run
    loop.run_forever()
  File "/usr/lib/python3.9/asyncio/base_events.py", line 596, in run_forever
    self._run_once()
  File "/usr/lib/python3.9/asyncio/base_events.py", line 1890, in _run_once
    handle._run()
  File "/usr/lib/python3.9/asyncio/events.py", line 80, in _run
    self._context.run(self._callback, *self._args)
  File "/home/hyper/.local/lib/python3.9/site-packages/discord/client.py", line 333, in _run_event
    await coro(*args, **kwargs)
  File "/home/hyper/Documents/Coding/Python/DiscordBot/bot.py", line 131, in on_message
    await bot.process_commands(message)
  File "/home/hyper/.local/lib/python3.9/site-packages/discord/ext/commands/bot.py", line 940, in process_commands
    await self.invoke(ctx)
  File "/home/hyper/.local/lib/python3.9/site-packages/discord/ext/commands/bot.py", line 903, in invoke
    await ctx.command.invoke(ctx)
  File "/home/hyper/.local/lib/python3.9/site-packages/discord/ext/commands/core.py", line 859, in invoke
    await injected(*ctx.args, **ctx.kwargs)
  File "/home/hyper/.local/lib/python3.9/site-packages/discord/ext/commands/core.py", line 85, in wrapped
    ret = await coro(*args, **kwargs)
  File "/home/hyper/Documents/Coding/Python/DiscordBot/bot.py", line 75, in command_reboot
    quit()
  File "/usr/lib/python3.9/_sitebuiltins.py", line 26, in __call__
    raise SystemExit(code)
SystemExit: None
---   SHUT DOWN.   ---
Ignoring exception in command clean:
Traceback (most recent call last):
  File "/home/hyper/.local/lib/python3.9/site-packages/discord/ext/commands/core.py", line 85, in wrapped
    ret = await coro(*args, **kwargs)
  File "/home/hyper/Documents/Coding/Python/DiscordBot/bot.py", line 103, in command_clean
    await ctx.channel.purge(limit=limit, bulk=False)
AttributeError: 'DMChannel' object has no attribute 'purge'

The above exception was the direct cause of the following exception:

Traceback (most recent call last):
  File "/home/hyper/.local/lib/python3.9/site-packages/discord/ext/commands/bot.py", line 903, in invoke
    await ctx.command.invoke(ctx)
  File "/home/hyper/.local/lib/python3.9/site-packages/discord/ext/commands/core.py", line 859, in invoke
    await injected(*ctx.args, **ctx.kwargs)
  File "/home/hyper/.local/lib/python3.9/site-packages/discord/ext/commands/core.py", line 94, in wrapped
    raise CommandInvokeError(exc) from exc
discord.ext.commands.errors.CommandInvokeError: Command raised an exception: AttributeError: 'DMChannel' object has no attribute 'purge'
--- STARTING UP... ---
[VB] User Hyperboid sent message "/tt clean 50"
---   CONNECTED.   ---
Connected!
[VB] User Hyperboid sent message "/tt rl"
_ClientEventTask exception was never retrieved
future: <ClientEventTask state=finished event=on_message coro=<function on_message at 0x7efd1f953ca0> exception=SystemExit(None)>
Traceback (most recent call last):
  File "/home/hyper/.local/lib/python3.9/site-packages/discord/client.py", line 698, in run
    loop.run_forever()
  File "/usr/lib/python3.9/asyncio/base_events.py", line 596, in run_forever
    self._run_once()
  File "/usr/lib/python3.9/asyncio/base_events.py", line 1890, in _run_once
    handle._run()
  File "/usr/lib/python3.9/asyncio/events.py", line 80, in _run
    self._context.run(self._callback, *self._args)
  File "/home/hyper/.local/lib/python3.9/site-packages/discord/client.py", line 333, in _run_event
    await coro(*args, **kwargs)
  File "/home/hyper/Documents/Coding/Python/DiscordBot/bot.py", line 131, in on_message
    await prettymsg(message.channel, "Only I'm allowed to `fricking` swear! <:WC:799371267849453581>.")
  File "/home/hyper/.local/lib/python3.9/site-packages/discord/ext/commands/bot.py", line 940, in process_commands
    await self.invoke(ctx)
  File "/home/hyper/.local/lib/python3.9/site-packages/discord/ext/commands/bot.py", line 903, in invoke
    await ctx.command.invoke(ctx)
  File "/home/hyper/.local/lib/python3.9/site-packages/discord/ext/commands/core.py", line 859, in invoke
    await injected(*ctx.args, **ctx.kwargs)
  File "/home/hyper/.local/lib/python3.9/site-packages/discord/ext/commands/core.py", line 85, in wrapped
    ret = await coro(*args, **kwargs)
  File "/home/hyper/Documents/Coding/Python/DiscordBot/bot.py", line 75, in command_reboot
    quit()
  File "/usr/lib/python3.9/_sitebuiltins.py", line 26, in __call__
    raise SystemExit(code)
SystemExit: None
---   SHUT DOWN.   ---
/home/hyper/Documents/Coding/Python/DiscordBot/bot.py:93: RuntimeWarning: coroutine 'prettymsg' was never awaited
  prettymsg(ctx, "Not yet implemented")
RuntimeWarning: Enable tracemalloc to get the object allocation traceback
--- STARTING UP... ---
---   CONNECTED.   ---
Connected!
[VB] User Hyperboid sent message "/tt clean 50"
[VB] User Tommy Trusty sent message ""
[VB] User BLAZR3R sent message "/TT WEIRDCHAMP"
[VB] User BLAZR3R sent message "/tt weirdchamp"
[VB] User Tommy Trusty sent message ""
[VB] User Hyperboid sent message "/tt swears true"
[VB] User Hyperboid sent message "/tt rl"
_ClientEventTask exception was never retrieved
future: <ClientEventTask state=finished event=on_message coro=<function on_message at 0x7f47c20ceca0> exception=SystemExit(None)>
Traceback (most recent call last):
  File "/home/hyper/.local/lib/python3.9/site-packages/discord/client.py", line 698, in run
    loop.run_forever()
  File "/usr/lib/python3.9/asyncio/base_events.py", line 596, in run_forever
    self._run_once()
  File "/usr/lib/python3.9/asyncio/base_events.py", line 1890, in _run_once
    handle._run()
  File "/usr/lib/python3.9/asyncio/events.py", line 80, in _run
    self._context.run(self._callback, *self._args)
  File "/home/hyper/.local/lib/python3.9/site-packages/discord/client.py", line 333, in _run_event
    await coro(*args, **kwargs)
  File "/home/hyper/Documents/Coding/Python/DiscordBot/bot.py", line 133, in on_message
    await bot.process_commands(message)
  File "/home/hyper/.local/lib/python3.9/site-packages/discord/ext/commands/bot.py", line 940, in process_commands
    await self.invoke(ctx)
  File "/home/hyper/.local/lib/python3.9/site-packages/discord/ext/commands/bot.py", line 903, in invoke
    await ctx.command.invoke(ctx)
  File "/home/hyper/.local/lib/python3.9/site-packages/discord/ext/commands/core.py", line 859, in invoke
    await injected(*ctx.args, **ctx.kwargs)
  File "/home/hyper/.local/lib/python3.9/site-packages/discord/ext/commands/core.py", line 85, in wrapped
    ret = await coro(*args, **kwargs)
  File "/home/hyper/Documents/Coding/Python/DiscordBot/bot.py", line 75, in command_reboot
    quit()
  File "/usr/lib/python3.9/_sitebuiltins.py", line 26, in __call__
    raise SystemExit(code)
SystemExit: None
---   SHUT DOWN.   ---
